<?xml version="1.0" encoding="utf-8"?>
<!-- This URDF was automatically created by SolidWorks to URDF Exporter! Originally created by Stephen Brawner (brawner@gmail.com) 
     Commit Version: 1.5.1-0-g916b5db  Build Version: 1.5.7152.31018
     For more information, please see http://wiki.ros.org/sw_urdf_exporter -->
<robot
  name="fingertest">
  <include filename="$(find fingertest)/urdf/fingertest.gazebo"/>
  <link
    name="base_link">
    <inertial>
      <origin
        xyz="-0.01 0.00 0.04"
        rpy="0 0 0" />
      <mass
        value="0.027" />
      <inertia
        ixx="0"
        ixy="0"
        ixz="0"
        iyy="0"
        iyz="0"
        izz="20" />
    </inertial>
    <visual>
      <origin
        xyz="0 0 0"
        rpy="0 0 0" />
      <geometry>
        <mesh
          filename="package://fingertest/meshes/base_link.STL" />
      </geometry>
      <material
        name="">
        <color
          rgba="0.898039215686275 0.917647058823529 0.929411764705882 1" />
      </material>
    </visual>
    <collision>
      <origin
        xyz="0 0 0"
        rpy="0 0 0" />
      <geometry>
        <mesh
          filename="package://fingertest/meshes/base_link.STL" />
      </geometry>
    </collision>
  </link>
  <link
    name="Link_1">
    <inertial>
      <origin
        xyz="0 -0.01 0.02"
        rpy="0 0 0" />
      <mass
        value="0.02" />
      <inertia
        ixx="0"
        ixy="0"
        ixz="0"
        iyy="0"
        iyz="0"
        izz="0" />
    </inertial>
    <visual>
      <origin
        xyz="0 0 0"
        rpy="0 0 0" />
      <geometry>
        <mesh
          filename="package://fingertest/meshes/Link_1.STL" />
      </geometry>
      <material
        name="">
        <color
          rgba="0.898039215686275 0.917647058823529 0.929411764705882 1" />
      </material>
    </visual>
    <collision>
      <origin
        xyz="0 0 0"
        rpy="0 0 0" />
      <geometry>
        <mesh
          filename="package://fingertest/meshes/Link_1.STL" />
      </geometry>
    </collision>
  </link>

  
  <link name="world"/>
  <joint name="fixed123" type="fixed">
    <origin
      xyz="0 0 0"
      rpy="0 0 0" />
    <parent
      link="world" />
    <child
      link="base_link" />
    <axis
      xyz="0 0 0" />
  </joint>
  
 
  
  <joint
    name="Joint1"
    type="continuous">
    <origin
      xyz="-0.0165 0 0.0301"
      rpy="0 0 0" />
    <parent
      link="base_link" />
    <child
      link="Link_1" />
    <axis
      xyz="0 -1 0" />
  </joint>
  <link
    name="Link_2">
    <inertial>
      <origin
        xyz="0 -0.01 0.01"
        rpy="0 0 0" />
      <mass
        value="0.0197910341256244" />
      <inertia
        ixx="0"
        ixy="0"
        ixz="0"
        iyy="0"
        iyz="0"
        izz="0" />
    </inertial>
    <visual>
      <origin
        xyz="0 0 0"
        rpy="0 0 0" />
      <geometry>
        <mesh
          filename="package://fingertest/meshes/Link_2.STL" />
      </geometry>
      <material
        name="">
        <color
          rgba="0.898039215686275 0.917647058823529 0.929411764705882 1" />
      </material>
    </visual>
    <collision>
      <origin
        xyz="0 0 0"
        rpy="0 0 0" />
      <geometry>
        <mesh
          filename="package://fingertest/meshes/Link_2.STL" />
      </geometry>
    </collision>
  </link>
  <joint
    name="Joint2"
    type="continuous">
    <origin
      xyz="0 0 0.05715"
      rpy="0 0 0" />
    <parent
      link="Link_1" />
    <child
      link="Link_2" />
    <axis
      xyz="0 -1 0" />
  </joint>
  <link
    name="Link_3">
    <inertial>
      <origin
        xyz="-0.02 0.01 0.00"
        rpy="0 0 0" />
      <mass
        value="0.027" />
      <inertia
        ixx="0"
        ixy="0"
        ixz="0"
        iyy="0"
        iyz="0"
        izz="0" />
    </inertial>
    <visual>
      <origin
        xyz="0 0 0"
        rpy="0 0 0" />
      <geometry>
        <mesh
          filename="package://fingertest/meshes/Link_3.STL" />
      </geometry>
      <material
        name="">
        <color
          rgba="0.898039215686275 0.917647058823529 0.929411764705882 1" />
      </material>
    </visual>
    <collision>
      <origin
        xyz="0 0 0"
        rpy="0 0 0" />
      <geometry>
        <mesh
          filename="package://fingertest/meshes/Link_3.STL" />
      </geometry>
    </collision>
  </link>
  <joint
    name="Joint3"
    type="continuous">
    <origin
      xyz="0 0 0.0381"
      rpy="0 0 0" />
    <parent
      link="Link_2" />
    <child
      link="Link_3" />
    <axis
      xyz="0 -1 0" />
  </joint>
</robot>
